<?xml version="1.0"?>
<!-- This URDF was automatically created by SolidWorks to URDF Exporter! Originally created by Stephen Brawner (brawner@gmail.com) 
     Commit Version:   Build Version: 1.6.9481.7103
     For more information, please see http://wiki.ros.org/sw_urdf_exporter -->
<robot
  name="master_bot">
  <!-- Base footprint link at ground level -->
  <link name="base_footprint">
    <visual>
      <origin xyz="0 0 0" rpy="0 0 0" />
      <geometry>
        <box size="0.001 0.001 0.001" />
      </geometry>
    </visual>
  </link>
  
  <!-- Joint connecting base_footprint to base_link -->
  <joint name="base_footprint_joint" type="fixed">
    <origin xyz="0 0 0.5" rpy="0 0 0" />
    <parent link="base_footprint" />
    <child link="base_link" />
  </joint>
  
  <link
    name="base_link">
    <inertial>
      <origin
        xyz="0.00890886340632199 -2.12108746995987E-05 -0.249771762086449"
        rpy="0 0 0" />
      <mass
        value="102.457212071935" />
      <inertia
        ixx="5.96593791507147"
        ixy="-0.000168989927705924"
        ixz="-0.221596004916151"
        iyy="3.39204393062452"
        iyz="0.000300406798158458"
        izz="6.96204879141497" />
    </inertial>
    <visual>
      <origin
        xyz="0 0 0"
        rpy="0 0 0" />
      <geometry>
        <mesh
          filename="package://master_bot/meshes/base_link.STL" />
      </geometry>
      <material
        name="">
        <color
          rgba="0.76078431372549 0.4 0.180392156862745 0.3" />
      </material>
    </visual>
    <collision>
      <origin
        xyz="0 0 0"
        rpy="0 0 0" />
      <geometry>
        <mesh
          filename="package://master_bot/meshes/base_link.STL" />
      </geometry>
    </collision>
  </link>
  <link
    name="l_l1">
    <inertial>
      <origin
        xyz="4.996E-16 -0.0719 2.7756E-17"
        rpy="0 0 0" />
      <mass
        value="2.1385" />
      <inertia
        ixx="0.0062157"
        ixy="1.2139E-17"
        ixz="-2.0788E-18"
        iyy="0.0050614"
        iyz="2.0255E-18"
        izz="0.0062157" />
    </inertial>
    <visual>
      <origin
        xyz="0 0 0"
        rpy="0 0 0" />
      <geometry>
        <mesh
          filename="package://master_bot/meshes/l_l1.STL" />
      </geometry>
      <material
        name="">
        <color
          rgba="0.38824 0.4 0.85882 0.3" />
      </material>
    </visual>
    <collision>
      <origin
        xyz="0 0 0"
        rpy="0 0 0" />
      <geometry>
        <mesh
          filename="package://master_bot/meshes/l_l1.STL" />
      </geometry>
    </collision>
  </link>
  <joint
    name="j_l1"
    type="continuous">
    <origin
      xyz="0.31373 0.3723 -0.33393"
      rpy="0 0 0" />
    <parent
      link="base_link" />
    <child
      link="l_l1" />
    <axis
      xyz="0 1 0" />
  </joint>
  <link
    name="l_l2">
    <inertial>
      <origin
        xyz="-5.5511E-17 -0.0739 1.3878E-17"
        rpy="0 0 0" />
      <mass
        value="0.89909" />
      <inertia
        ixx="0.0020719"
        ixy="-4.7629E-19"
        ixz="8.3461E-21"
        iyy="0.00087046"
        iyz="2.4619E-19"
        izz="0.0020719" />
    </inertial>
    <visual>
      <origin
        xyz="0 0 0"
        rpy="0 0 0" />
      <geometry>
        <mesh
          filename="package://master_bot/meshes/l_l2.STL" />
      </geometry>
      <material
        name="">
        <color
          rgba="0.38824 0.85882 0.38824 0.3" />
      </material>
    </visual>
    <collision>
      <origin
        xyz="0 0 0"
        rpy="0 0 0" />
      <geometry>
        <mesh
          filename="package://master_bot/meshes/l_l2.STL" />
      </geometry>
    </collision>
  </link>
  <joint
    name="j_l2"
    type="continuous">
    <origin
      xyz="0.21333 0.3763 -0.45648"
      rpy="0 0 0" />
    <parent
      link="base_link" />
    <child
      link="l_l2" />
    <axis
      xyz="0 1 0" />
  </joint>
  <link
    name="l_l3">
    <inertial>
      <origin
        xyz="-2.7756E-17 -0.0739 2.7756E-17"
        rpy="0 0 0" />
      <mass
        value="0.89909" />
      <inertia
        ixx="0.0020719"
        ixy="-3.3003E-19"
        ixz="-8.3461E-21"
        iyy="0.00087046"
        iyz="2.5891E-19"
        izz="0.0020719" />
    </inertial>
    <visual>
      <origin
        xyz="0 0 0"
        rpy="0 0 0" />
      <geometry>
        <mesh
          filename="package://master_bot/meshes/l_l3.STL" />
      </geometry>
      <material
        name="">
        <color
          rgba="0.38824 0.85882 0.38824 0.3" />
      </material>
    </visual>
    <collision>
      <origin
        xyz="0 0 0"
        rpy="0 0 0" />
      <geometry>
        <mesh
          filename="package://master_bot/meshes/l_l3.STL" />
      </geometry>
    </collision>
  </link>
  <joint
    name="j_l3"
    type="continuous">
    <origin
      xyz="0.11783 0.3723 -0.45648"
      rpy="0 0 0" />
    <parent
      link="base_link" />
    <child
      link="l_l3" />
    <axis
      xyz="0 1 0" />
  </joint>
  <link
    name="l_l4">
    <inertial>
      <origin
        xyz="-1.38777878078145E-17 -0.0739000000000003 1.38777878078145E-17"
        rpy="0 0 0" />
      <mass
        value="0.899087226846545" />
      <inertia
        ixx="0.00207193192008918"
        ixy="-3.19702190316086E-19"
        ixz="8.34609797361173E-21"
        iyy="0.00087046107076059"
        iyz="2.69240255571735E-19"
        izz="0.00207193192008918" />
    </inertial>
    <visual>
      <origin
        xyz="0 0 0"
        rpy="0 0 0" />
      <geometry>
        <mesh
          filename="package://master_bot/meshes/l_l4.STL" />
      </geometry>
      <material
        name="">
        <color
          rgba="0.388235294117647 0.858823529411765 0.388235294117647 0.3" />
      </material>
    </visual>
    <collision>
      <origin
        xyz="0 0 0"
        rpy="0 0 0" />
      <geometry>
        <mesh
          filename="package://master_bot/meshes/l_l4.STL" />
      </geometry>
    </collision>
  </link>
  <joint
    name="j_l4"
    type="continuous">
    <origin
      xyz="0.022322 0.3723 -0.45648"
      rpy="0 0 0" />
    <parent
      link="base_link" />
    <child
      link="l_l4" />
    <axis
      xyz="0 1 0" />
  </joint>
  <link
    name="l_l5">
    <inertial>
      <origin
        xyz="-2.7756E-17 -0.0739 1.3878E-17"
        rpy="0 0 0" />
      <mass
        value="0.89909" />
      <inertia
        ixx="0.0020719"
        ixy="-3.3003E-19"
        ixz="-8.3461E-21"
        iyy="0.00087046"
        iyz="2.9229E-19"
        izz="0.0020719" />
    </inertial>
    <visual>
      <origin
        xyz="0 0 0"
        rpy="0 0 0" />
      <geometry>
        <mesh
          filename="package://master_bot/meshes/l_l5.STL" />
      </geometry>
      <material
        name="">
        <color
          rgba="0.38824 0.85882 0.38824 0.3" />
      </material>
    </visual>
    <collision>
      <origin
        xyz="0 0 0"
        rpy="0 0 0" />
      <geometry>
        <mesh
          filename="package://master_bot/meshes/l_l5.STL" />
      </geometry>
    </collision>
  </link>
  <joint
    name="j_l5"
    type="continuous">
    <origin
      xyz="-0.073182 0.3723 -0.45648"
      rpy="0 0 0" />
    <parent
      link="base_link" />
    <child
      link="l_l5" />
    <axis
      xyz="0 1 0" />
  </joint>
  <link
    name="l_l6">
    <inertial>
      <origin
        xyz="0 -0.0739 1.3878E-17"
        rpy="0 0 0" />
      <mass
        value="0.89909" />
      <inertia
        ixx="0.0020719"
        ixy="-5.6218E-20"
        ixz="7.5115E-20"
        iyy="0.00087046"
        iyz="2.3824E-19"
        izz="0.0020719" />
    </inertial>
    <visual>
      <origin
        xyz="0 0 0"
        rpy="0 0 0" />
      <geometry>
        <mesh
          filename="package://master_bot/meshes/l_l6.STL" />
      </geometry>
      <material
        name="">
        <color
          rgba="0.38824 0.85882 0.38824 0.3" />
      </material>
    </visual>
    <collision>
      <origin
        xyz="0 0 0"
        rpy="0 0 0" />
      <geometry>
        <mesh
          filename="package://master_bot/meshes/l_l6.STL" />
      </geometry>
    </collision>
  </link>
  <joint
    name="j_l6"
    type="continuous">
    <origin
      xyz="-0.16868 0.3723 -0.45648"
      rpy="0 0 0" />
    <parent
      link="base_link" />
    <child
      link="l_l6" />
    <axis
      xyz="0 1 0" />
  </joint>
  <link
    name="l_l7">
    <inertial>
      <origin
        xyz="4.4409E-16 -0.0719 3.8164E-17"
        rpy="0 0 0" />
      <mass
        value="2.1385" />
      <inertia
        ixx="0.0062157"
        ixy="1.2165E-17"
        ixz="-2.0788E-18"
        iyy="0.0050614"
        iyz="2.0255E-18"
        izz="0.0062157" />
    </inertial>
    <visual>
      <origin
        xyz="0 0 0"
        rpy="0 0 0" />
      <geometry>
        <mesh
          filename="package://master_bot/meshes/l_l7.STL" />
      </geometry>
      <material
        name="">
        <color
          rgba="0.38824 0.4 0.85882 0.3" />
      </material>
    </visual>
    <collision>
      <origin
        xyz="0 0 0"
        rpy="0 0 0" />
      <geometry>
        <mesh
          filename="package://master_bot/meshes/l_l7.STL" />
      </geometry>
    </collision>
  </link>
  <joint
    name="j_l7"
    type="continuous">
    <origin
      xyz="-0.25069 0.3723 -0.36114"
      rpy="0 0 0" />
    <parent
      link="base_link" />
    <child
      link="l_l7" />
    <axis
      xyz="0 1 0" />
  </joint>
  <link
    name="l_r1">
    <inertial>
      <origin
        xyz="5.5511E-16 0.0719 -2.7756E-17"
        rpy="0 0 0" />
      <mass
        value="2.1385" />
      <inertia
        ixx="0.0062157"
        ixy="-4.048E-18"
        ixz="-1.0394E-18"
        iyy="0.0050614"
        iyz="1.7325E-18"
        izz="0.0062157" />
    </inertial>
    <visual>
      <origin
        xyz="0 0 0"
        rpy="0 0 0" />
      <geometry>
        <mesh
          filename="package://master_bot/meshes/l_r1.STL" />
      </geometry>
      <material
        name="">
        <color
          rgba="0.38824 0.4 0.85882 0.3" />
      </material>
    </visual>
    <collision>
      <origin
        xyz="0 0 0"
        rpy="0 0 0" />
      <geometry>
        <mesh
          filename="package://master_bot/meshes/l_r1.STL" />
      </geometry>
    </collision>
  </link>
  <joint
    name="j_r1"
    type="continuous">
    <origin
      xyz="0.31373 -0.3723 -0.33393"
      rpy="0 0 0" />
    <parent
      link="base_link" />
    <child
      link="l_r1" />
    <axis
      xyz="0 1 0" />
  </joint>
  <link
    name="l_r2">
    <inertial>
      <origin
        xyz="0 0.0739000000000003 -1.38777878078145E-17"
        rpy="0 0 0" />
      <mass
        value="0.899087226846545" />
      <inertia
        ixx="0.00207193192008918"
        ixy="-4.30522915276281E-19"
        ixz="7.51148817625116E-20"
        iyy="0.00087046107076059"
        iyz="2.89688856794641E-19"
        izz="0.00207193192008918" />
    </inertial>
    <visual>
      <origin
        xyz="0 0 0"
        rpy="0 0 0" />
      <geometry>
        <mesh
          filename="package://master_bot/meshes/l_r2.STL" />
      </geometry>
      <material
        name="">
        <color
          rgba="0.388235294117647 0.858823529411765 0.388235294117647 0.3" />
      </material>
    </visual>
    <collision>
      <origin
        xyz="0 0 0"
        rpy="0 0 0" />
      <geometry>
        <mesh
          filename="package://master_bot/meshes/l_r2.STL" />
      </geometry>
    </collision>
  </link>
  <joint
    name="j_r2"
    type="continuous">
    <origin
      xyz="0.21333 -0.3763 -0.45648"
      rpy="0 0 0" />
    <parent
      link="base_link" />
    <child
      link="l_r2" />
    <axis
      xyz="0 1 0" />
  </joint>
  <link
    name="l_r3">
    <inertial>
      <origin
        xyz="0 0.0739 -1.3878E-17"
        rpy="0 0 0" />
      <mass
        value="0.89909" />
      <inertia
        ixx="0.0020719"
        ixy="-2.8427E-19"
        ixz="-8.3461E-21"
        iyy="0.00087046"
        iyz="3.3579E-19"
        izz="0.0020719" />
    </inertial>
    <visual>
      <origin
        xyz="0 0 0"
        rpy="0 0 0" />
      <geometry>
        <mesh
          filename="package://master_bot/meshes/l_r3.STL" />
      </geometry>
      <material
        name="">
        <color
          rgba="0.38824 0.85882 0.38824 0.3" />
      </material>
    </visual>
    <collision>
      <origin
        xyz="0 0 0"
        rpy="0 0 0" />
      <geometry>
        <mesh
          filename="package://master_bot/meshes/l_r3.STL" />
      </geometry>
    </collision>
  </link>
  <joint
    name="j_r3"
    type="continuous">
    <origin
      xyz="0.11783 -0.3723 -0.45648"
      rpy="0 0 0" />
    <parent
      link="base_link" />
    <child
      link="l_r3" />
    <axis
      xyz="0 1 0" />
  </joint>
  <link
    name="l_r4">
    <inertial>
      <origin
        xyz="2.0817E-17 0.0739 -1.3878E-17"
        rpy="0 0 0" />
      <mass
        value="0.89909" />
      <inertia
        ixx="0.0020719"
        ixy="-3.0732E-19"
        ixz="7.5115E-20"
        iyy="0.00087046"
        iyz="3.1274E-19"
        izz="0.0020719" />
    </inertial>
    <visual>
      <origin
        xyz="0 0 0"
        rpy="0 0 0" />
      <geometry>
        <mesh
          filename="package://master_bot/meshes/l_r4.STL" />
      </geometry>
      <material
        name="">
        <color
          rgba="0.38824 0.85882 0.38824 0.3" />
      </material>
    </visual>
    <collision>
      <origin
        xyz="0 0 0"
        rpy="0 0 0" />
      <geometry>
        <mesh
          filename="package://master_bot/meshes/l_r4.STL" />
      </geometry>
    </collision>
  </link>
  <joint
    name="j_r4"
    type="continuous">
    <origin
      xyz="0.022322 -0.3723 -0.45648"
      rpy="0 0 0" />
    <parent
      link="base_link" />
    <child
      link="l_r4" />
    <axis
      xyz="0 1 0" />
  </joint>
  <link
    name="l_r5">
    <inertial>
      <origin
        xyz="0 0.0739000000000002 -1.38777878078145E-17"
        rpy="0 0 0" />
      <mass
        value="0.899087226846545" />
      <inertia
        ixx="0.00207193192008918"
        ixy="-2.9024408336068E-19"
        ixz="-8.34609797361175E-21"
        iyy="0.00087046107076059"
        iyz="3.35792634578967E-19"
        izz="0.00207193192008918" />
    </inertial>
    <visual>
      <origin
        xyz="0 0 0"
        rpy="0 0 0" />
      <geometry>
        <mesh
          filename="package://master_bot/meshes/l_r5.STL" />
      </geometry>
      <material
        name="">
        <color
          rgba="0.388235294117647 0.858823529411765 0.388235294117647 0.3" />
      </material>
    </visual>
    <collision>
      <origin
        xyz="0 0 0"
        rpy="0 0 0" />
      <geometry>
        <mesh
          filename="package://master_bot/meshes/l_r5.STL" />
      </geometry>
    </collision>
  </link>
  <joint
    name="j_r5"
    type="continuous">
    <origin
      xyz="-0.073182 -0.3723 -0.45648"
      rpy="0 0 0" />
    <parent
      link="base_link" />
    <child
      link="l_r5" />
    <axis
      xyz="0 1 0" />
  </joint>
  <link
    name="l_r6">
    <inertial>
      <origin
        xyz="0 0.0739 -1.3878E-17"
        rpy="0 0 0" />
      <mass
        value="0.89909" />
      <inertia
        ixx="0.0020719"
        ixy="-7.124E-20"
        ixz="1.085E-19"
        iyy="0.00087046"
        iyz="3.1513E-19"
        izz="0.0020719" />
    </inertial>
    <visual>
      <origin
        xyz="0 0 0"
        rpy="0 0 0" />
      <geometry>
        <mesh
          filename="package://master_bot/meshes/l_r6.STL" />
      </geometry>
      <material
        name="">
        <color
          rgba="0.38824 0.85882 0.38824 0.3" />
      </material>
    </visual>
    <collision>
      <origin
        xyz="0 0 0"
        rpy="0 0 0" />
      <geometry>
        <mesh
          filename="package://master_bot/meshes/l_r6.STL" />
      </geometry>
    </collision>
  </link>
  <joint
    name="j_r6"
    type="continuous">
    <origin
      xyz="-0.16868 -0.3723 -0.45648"
      rpy="0 0 0" />
    <parent
      link="base_link" />
    <child
      link="l_r6" />
    <axis
      xyz="0 1 0" />
  </joint>
  <link
    name="l_r7">
    <inertial>
      <origin
        xyz="4.996E-16 0.0719 -1.7347E-17"
        rpy="0 0 0" />
      <mass
        value="2.1385" />
      <inertia
        ixx="0.0062157"
        ixy="-4.048E-18"
        ixz="-1.0394E-18"
        iyy="0.0050614"
        iyz="1.4727E-18"
        izz="0.0062157" />
    </inertial>
    <visual>
      <origin
        xyz="0 0 0"
        rpy="0 0 0" />
      <geometry>
        <mesh
          filename="package://master_bot/meshes/l_r7.STL" />
      </geometry>
      <material
        name="">
        <color
          rgba="0.38824 0.4 0.85882 0.3" />
      </material>
    </visual>
    <collision>
      <origin
        xyz="0 0 0"
        rpy="0 0 0" />
      <geometry>
        <mesh
          filename="package://master_bot/meshes/l_r7.STL" />
      </geometry>
    </collision>
  </link>
  <joint
    name="j_r7"
    type="continuous">
    <origin
      xyz="-0.25069 -0.3723 -0.36114"
      rpy="0 0 0" />
    <parent
      link="base_link" />
    <child
      link="l_r7" />
    <axis
      xyz="0 1 0" />
  </joint>
  <link
    name="l_BL2">
    <inertial>
      <origin
        xyz="8.2345E-05 9.7401E-16 -0.56913"
        rpy="0 0 0" />
      <mass
        value="0.058407" />
      <inertia
        ixx="1.5913E-05"
        ixy="-9.1307E-21"
        ixz="-8.7184E-07"
        iyy="1.6147E-05"
        iyz="4.2082E-21"
        izz="1.2893E-05" />
    </inertial>
    <visual>
      <origin
        xyz="0 0 0"
        rpy="0 0 0" />
      <geometry>
        <mesh
          filename="package://master_bot/meshes/l_FL2.STL" />
      </geometry>
      <material
        name="">
        <color
          rgba="0.79216 0.81961 0.93333 1" />
      </material>
    </visual>
    <collision>
      <origin
        xyz="0 0 0"
        rpy="0 0 0" />
      <geometry>
        <mesh
          filename="package://master_bot/meshes/l_FL2.STL" />
      </geometry>
    </collision>
  </link>
  <joint
    name="j_BL2"
    type="fixed">
    <origin
      xyz="-0.26408 0 -0.17156"
      rpy="0 -1.5708 0" />
    <parent
      link="base_link" />
    <child
      link="l_BL2" />
    <axis
      xyz="0 0 0" />
  </joint>
  <link
    name="l_FL2">
    <inertial>
      <origin
        xyz="0.14157 -9.3649E-16 -0.55049"
        rpy="0 0 0" />
      <mass
        value="0.022313" />
      <inertia
        ixx="4.5006E-06"
        ixy="3.3646E-24"
        ixz="7.1047E-07"
        iyy="4.65E-06"
        iyz="2.2296E-22"
        izz="2.0395E-06" />
    </inertial>
    <visual>
      <origin
        xyz="0 0 0"
        rpy="0 0 0" />
      <geometry>
        <mesh
          filename="package://master_bot/meshes/l_BL2.STL" />
      </geometry>
      <material
        name="">
        <color
          rgba="0.79216 0.81961 0.93333 1" />
      </material>
    </visual>
    <collision>
      <origin
        xyz="0 0 0"
        rpy="0 0 0" />
      <geometry>
        <mesh
          filename="package://master_bot/meshes/l_BL2.STL" />
      </geometry>
    </collision>
  </link>
  <joint
    name="j_FL2"
    type="fixed">
    <origin
      xyz="0.32674 0 -0.17729"
      rpy="-3.1416 1.309 -3.1416" />
    <parent
      link="base_link" />
    <child
      link="l_FL2" />
    <axis
      xyz="0 0 0" />
  </joint>

  <!-- Front Unitree L2 LiDAR Sensor (Gazebo Fortress) -->
  <!-- Note: Physical front position now uses l_BL2 link name (swapped) -->
  <gazebo reference="l_BL2">
    <sensor name="front_lidar" type="gpu_lidar">
      <pose>0 0 0 0 0 0</pose>
      <visualize>true</visualize>
      <update_rate>10</update_rate>
      <topic>lidar_front/pointcloud</topic>
      <lidar>
        <scan>
          <horizontal>
            <samples>1024</samples>
            <resolution>1</resolution>
            <min_angle>-3.14159</min_angle>
            <max_angle>3.14159</max_angle>
          </horizontal>
          <vertical>
            <samples>32</samples>
            <resolution>1</resolution>
            <min_angle>-0.84</min_angle>
            <max_angle>0.84</max_angle>
          </vertical>
        </scan>
        <range>
          <min>0.05</min>
          <max>30.0</max>
          <resolution>0.02</resolution>
        </range>
        <noise>
          <type>gaussian</type>
          <mean>0.0</mean>
          <stddev>0.01</stddev>
        </noise>
      </lidar>
      <ignition_frame_id>l_BL2</ignition_frame_id>
    </sensor>
  </gazebo>

  <!-- Rear Unitree L2 LiDAR Sensor (Gazebo Fortress) -->
  <!-- Note: Physical rear position now uses l_FL2 link name (swapped) -->
  <gazebo reference="l_FL2">
    <sensor name="rear_lidar" type="gpu_lidar">
      <pose>0 0 0 0 0 0</pose>
      <visualize>true</visualize>
      <update_rate>10</update_rate>
      <topic>lidar_rear/pointcloud</topic>
      <lidar>
        <scan>
          <horizontal>
            <samples>1024</samples>
            <resolution>1</resolution>
            <min_angle>-3.14159</min_angle>
            <max_angle>3.14159</max_angle>
          </horizontal>
          <vertical>
            <samples>32</samples>
            <resolution>1</resolution>
            <min_angle>-0.84</min_angle>
            <max_angle>0.84</max_angle>
          </vertical>
        </scan>
        <range>
          <min>0.05</min>
          <max>30.0</max>
          <resolution>0.02</resolution>
        </range>
        <noise>
          <type>gaussian</type>
          <mean>0.0</mean>
          <stddev>0.01</stddev>
        </noise>
      </lidar>
      <ignition_frame_id>l_FL2</ignition_frame_id>
    </sensor>
  </gazebo>

  <!-- GNSS Antenna Link (ZED-F9P) -->
  <link name="gnss_link">
    <inertial>
      <origin xyz="0 0 0" rpy="0 0 0" />
      <mass value="0.05" />
      <inertia
        ixx="0.00001" ixy="0" ixz="0"
        iyy="0.00001" iyz="0"
        izz="0.00001" />
    </inertial>
    <visual>
      <origin xyz="0 0 0" rpy="0 0 0" />
      <geometry>
        <cylinder radius="0.025" length="0.01" />
      </geometry>
      <material name="">
        <color rgba="1.0 0.5 0.0 1.0" /> <!-- Orange -->
      </material>
    </visual>
    <collision>
      <origin xyz="0 0 0" rpy="0 0 0" />
      <geometry>
        <cylinder radius="0.025" length="0.01" />
      </geometry>
    </collision>
  </link>

  <joint name="gnss_joint" type="fixed">
    <origin xyz="0 0.1 0" rpy="0 0 0" /> <!-- 10cm to the left of base_link -->
    <parent link="base_link" />
    <child link="gnss_link" />
  </joint>

</robot>